Workbook

Sheet Instructions
A1: TRT Nobox products · Nobox
A2: This file lists every Nobox product loaded into the inventory app, with its opening stock. It is also the upload template.
A4: How to use it
A5: 1. To add stock: put only the new quantities in Quantity_Added (Lagos) / (Abuja) and upload with Import from Excel on the Nobox dashboard. Each quantity is posted as a Stock Addition.
A6: 2. Clear the quantity columns before re-uploading this file, or the opening stock is added a second time.
A7: 3. New product: add a row with at least Material_Code and Material_Name. Products held in both cities need a quantity in both columns.
A8: 4. Keep the header row as it is. Do not add columns; the app rejects columns it does not know. Rows can be in any order.
A9: 5. If any row has a problem, nothing is uploaded. The app lists every problem by row and column.
A10: 6. Photos are added in the app: click the photo square beside a product on the Nobox dashboard. Products without a photo show a placeholder.
A12: Sheets
A13: Inventory_Master | B13: The products. Header frozen, filterable, with drop-downs for Unit and Category and checks on quantities.
A14: Summary | B14: Products and stock per category, calculated from Inventory_Master.
A15: Lists | B15: The allowed Units and the current Categories. Add to them here first.
A16: Review | B16: Rows worth checking: generated codes, codes that read like descriptions, missing Category or Unit, shared codes, removed duplicates.
A18: Column | B18: Rule
A19: Material_Code | B19: Required in this file. Several products may share a code when their name, subcategory, specification or dimensions differ (e.g. YXJ-0042 in MATT GOLD 1 METRE and MATT GOLD 25CM).
A20: Material_Name | B20: Required. What designers search for.
A21: Category / Subcategory | B21: Group products in the app's filters. Use the Lists sheet's spelling.
A22: Specification | B22: e.g. 18MM, 12 VOLTS.
A23: Dimensions (W*D*H)MM | B23: Width*Depth*Height in millimetres, e.g. 864*545*545.
A24: Unit | B24: PCS, PACK, CARTON, SHEET, ROLL, SET.
A25: Quantity_Added (Lagos) / (Abuja) | B25: 0 or more. New product: its opening stock in that store. Existing product: posted as a Stock Addition. Blank leaves that store alone.
... A28: Notes | B28: Kept on the product.

Sheet Inventory_Master
A1: Material_Code | B1: Material_Name | C1: Category | D1: Subcategory | E1: Specification | F1: Dimensions (W*D*H)MM | G1: Unit | H1: Quantity_Added (Lagos) | I1: Quantity_Added (Abuja) | J1: Reorder_Level | K1: Reorder_Quantity | L1: Supplier_or_Reference | M1: Document_Ref | N1: Notes
A2: CASHMIR-COPPER | B2: CASHMIR COPPER | C2: AGT | D2: BOARD | F2: 4*9 18MM | G2: SHEET | H2: 0
A3: CHROME-GREY | B3: CHROME GREY | C3: AGT | D3: BOARD | F3: 4*9 18MM | G3: SHEET | H3: 0
A4: EPHESUS-BLACK | B4: EPHESUS BLACK | C4: AGT | D4: BOARD | F4: 4*9 18MM | G4: SHEET | H4: 0
A5: GALAXY-DORE | B5: GALAXY DORE | C5: AGT | D5: BOARD | F5: 4*9 18MM | G5: SHEET | H5: 0
A6: H-G-DELUXE-GREY | B6: H.G DELUXE GREY | C6: AGT | D6: BOARD | F6: 4*9 18MM | G6: SHEET | H6: 0
A7: HG-GALAXY-CREAM | B7: HG GALAXY CREAM | C7: AGT | D7: BOARD | F7: 4*9 18MM | G7: SHEET | H7: 0
A8: HG-WHITE | B8: HG WHITE | C8: AGT | D8: BOARD | F8: 4*9 18MM | G8: SHEET | H8: 0
A9: LUX-WHITE | B9: LUX WHITE | C9: AGT | D9: BOARD | F9: 4*9 18MM | G9: SHEET | H9: 0
A10: MATT-STONE-GREY | B10: MATT STONE GREY | C10: AGT | D10: BOARD | F10: 4*9 18MM | G10: SHEET | H10: 0
A11: RELAX-GREEN | B11: RELAX GREEN | C11: AGT | D11: BOARD | F11: 4*9 18MM | G11: SHEET | H11: 0
A12: SOFT-TOUCH-OCEAN-BLUE | B12: SOFT TOUCH OCEAN BLUE | C12: AGT | D12: BOARD | F12: 4*9 18MM | G12: SHEET | H12: 0
A13: SOFT-TOUCH-STONE-GREY | B13: SOFT TOUCH STONE GREY | C13: AGT | D13: BOARD | F13: 4*9 18MM | G13: SHEET | H13: 0
... A30: TERRA-BROWN | B30: TERRA BROWN | C30: AGT | D30: EDGE TAPE | F30: EDGE TAPE SIZE 22 | G30: ROLL | H30: 0
A31: 609 900 | B31: EXTRACTOR RANGEHOOD | C31: APPLIANCES | D31: EXTRACTOR | G31: CARTON | H31: 0
A32: 909 900 | B32: GERMANIA RANGE HOOD | C32: APPLIANCES | D32: EXTRACTOR | G32: CARTON | H32: 6
A33: LAP60GG401 | B33: GERMANIA BUILT IN GAS HOB | C33: APPLIANCES | D33: GAS HOB | G33: CARTON | H33: 1
A34: LAP90SG501 | B34: GERMANIA BUILT IN GAS HOB | C34: APPLIANCES | D34: GAS HOB | G34: CARTON | H34: 2
A35: LAP-25MW101 | B35: BUILT-IN MICROWAVE OVEN | C35: APPLIANCES | D35: MICROWAVE | G35: CARTON | H35: 27
A36: LAP-44MV201 | B36: BUILT-IN COMPACT OVEN | C36: APPLIANCES | D36: OVEN | G36: CARTON | H36: 9
A37: LAP-V301 | B37: BUILT-IN OVEN | C37: APPLIANCES | D37: OVEN | G37: CARTON | H37: 17
A38: GERMANA LAP60SS021 | B38: DOUBLE DOOR STAINLESS STEEL REFRIGERATOR | C38: APPLIANCES | D38: REFRIGERATOR | G38: CARTON | H38: 13
A39: GERMANA LAP60SS02B | B39: DOUBLE DOOR BLACK REFRIGERATOR | C39: APPLIANCES | D39: REFRIGERATOR | G39: CARTON | H39: 6
A40: SAP-1WH602 | B40: INSTANT ELECTRIC WATER HEATER | C40: APPLIANCES | D40: WATER HEATER | G40: CARTON | H40: 2
A41: SAP30WH601 | B41: SEALED STORAGE ELECTRIC WATER HEATER | C41: APPLIANCES | D41: WATER HEATER | G41: CARTON | H41: 2
A42: HKDCP500A03 | B42: DTC CUTLERY TRAY | C42: DTC | D42: CUTLERY TRAY | E42: Compact flat Cutlery tray, 500mm length, grey matt | F42: LENGTH- 500MM | G42: PCS | H42: 0
A43: C85B6A6H+ | B43: HINGES | C43: DTC | D43: HALF OVERLAY | E43: C85B SERIES SNAP ON SOFT CLOSE HINGES,100 DEG OPENING, ONE WAY HALF OVERLAY, WITH CAM ADJUSTABLE MOUNTING PLATE, H=0 HOLE DISTANCES ON HINGES CUP=48MM 3D HINGES | G43: PCS | H43: 245
A44: SF00AH02A | B44: DTC LIFTING SYSTEM | C44: DTC | D44: LIFTING SYSTEM | E44: Top stays SF series soft close lifting system. Power factor(LF)=3200-9000kg*mm, Suit for cabinet height 250500mm. White color cover cap. Opening angle:107 deg, 3D adjustment(height/depth/side) | G44: PACK | H44: 41
A45: SQ02BC03A | B45: DTC LIFTING SYSTEM | C45: DTC | D45: LIFTING SYSTEM | G45: PACK | H45: 62
A46: SQ02BH03A | B46: DTC LIFTING SYSTEM | C46: DTC | D46: LIFTING SYSTEM | G46: PACK | H46: 53
A47: SQ02BM03A | B47: DTC LIFTING SYSTEM | C47: DTC | D47: LIFTING SYSTEM | E47: IN WHITE Top stays SQ series soft close lifting system. Power factor (LF)=960-2350kg*mm, Suit for cabinet height 250500mm. White color cover cap. Opening angle:107 deg, 3D adjustment(height/depth/side | G47: PACK | H47: 58
A48: SQ02BM03B | B48: DTC LIFTING SYSTEM | C48: DTC | D48: LIFTING SYSTEM | E48: IN GREY Top stays SQ series soft close lifting system.Power factor(LF)=960-2350kg*mm, Suit for cabinet height 250500mm. Grey color cover cap. Opening angle:107 deg, 3D adjustment(height/depth/side) | G48: PACK | H48: 29
A49: C98A276+H00AZ | B49: HINGES | C49: DTC | D49: NON HYDROLIC HINGES | E49: C98A SERIES SLIDE ON HINGES 110 DEG, TWO WAYS FULL OVERLAY, WITH TWO HOLES SLIDES- ON MOUNTING PLATE H=0 HOLE DISTANCES ON HINGES CUP=48MM | G49: PCS | H49: 2849
A50: HE10022 | B50: DRAWER PANEL | C50: DTC | D50: PANEL | F50: LENGTH 1100MM | G50: PCS | H50: 76
A51: 4587114H(350MM) | B51: SIDE RUNNERS | C51: DTC | D51: SIDE RUNNER | E51: 45MM SERIES SOFT CLOSE ROUND PROFILE FULL EXTENSIONBALL BEARING SLIDES-METRIC SIZES, 350MM | F51: 350MM | G51: PCS | H51: 57
A52: 4587116H(400MM) | B52: SIDE RUNNERS | C52: DTC | D52: SIDE RUNNER | E52: 45MM SERIES SOFT CLOSE ROUND PROFILE FULL EXTENSIONBALL BEARING SLIDES-METRIC SIZES, 400MM | F52: 400MM | G52: PCS | H52: 40
A53: 4587120H(500MM) | B53: SIDE RUNNERS | C53: DTC | D53: SIDE RUNNER | E53: 45MM SERIES SOFT CLOSE ROUND PROFILE FULL EXTENSIONBALL BEARING SLIDES-METRIC SIZES, 500MM | F53: 500MM | G53: PCS | H53: 161
A54: HD115004A11 | B54: DRAWER RUNNER | C54: DTC | D54: SMART BOX | E54: MAGIC STAR PLUS HD SERIES, LOW DRAWER FOR 16MM BODRD SOFT CLOSE, TILT ADJUSTMENT AT SIDE, HEIGHT =88MM, NL=500MM | F54: HEIGHT- 88MM, LENGTH- 500MM | G54: CARTON | H54: 94
A55: HD125004A11 | B55: DRAWER RUNNER | C55: DTC | D55: SMART BOX | E55: MAGIC STAR PLUS HD SERIES, LOW DRAWER FOR 16MM BODRD SOFT CLOSE, TILT ADJUSTMENT AT SIDE, HEIGHT =126MM, NL=500MM | F55: HEIGHT- 126MM, LEGHT- 500MM | G55: CARTON | H55: 117
A56: HD135004A11 | B56: DRAWER RUNNER | C56: DTC | D56: SMART BOX | E56: MAGIC STAR PLUS HD SERIES, LOW DRAWER FOR 16MM BODRD SOFT CLOSE, TILT ADJUSTMENT AT SIDE, HEIGHT =174MM, NL=500MM | F56: HEIGHT- 174MM, LENGTH- 500MM | G56: CARTON | H56: 33
...

Sheet Lists
A1: Unit | B1: Category | C1: Location
A2: CARTON | B2: AGT | C2: Lagos
A3: PACK | B3: APPLIANCES | C3: Abuja
A4: PCS | B4: DTC
A5: ROLL | B5: FINSA
A6: SET | B6: HANDLE
A7: SHEET | B7: KITCHEN ACCESSORIES
B8: KNOB
B9: MFC
B10: WARDROBE ACCESSORIES

Sheet Summary
A1: Category | B1: Materials | C1: Lagos qty | D1: Abuja qty
A2: AGT | B2: =COUNTIF(Inventory_Master!$C$2:$C$304,A2) | C2: =SUMIF(Inventory_Master!$C$2:$C$304,A2,Inventory_Master!$H$2:$H$304) | D2: =SUMIF(Inventory_Master!$C$2:$C$304,A2,Inventory_Master!$I$2:$I$304)
A3: APPLIANCES | B3: =COUNTIF(Inventory_Master!$C$2:$C$304,A3) | C3: =SUMIF(Inventory_Master!$C$2:$C$304,A3,Inventory_Master!$H$2:$H$304) | D3: =SUMIF(Inventory_Master!$C$2:$C$304,A3,Inventory_Master!$I$2:$I$304)
A4: DTC | B4: =COUNTIF(Inventory_Master!$C$2:$C$304,A4) | C4: =SUMIF(Inventory_Master!$C$2:$C$304,A4,Inventory_Master!$H$2:$H$304) | D4: =SUMIF(Inventory_Master!$C$2:$C$304,A4,Inventory_Master!$I$2:$I$304)
A5: FINSA | B5: =COUNTIF(Inventory_Master!$C$2:$C$304,A5) | C5: =SUMIF(Inventory_Master!$C$2:$C$304,A5,Inventory_Master!$H$2:$H$304) | D5: =SUMIF(Inventory_Master!$C$2:$C$304,A5,Inventory_Master!$I$2:$I$304)
A6: HANDLE | B6: =COUNTIF(Inventory_Master!$C$2:$C$304,A6) | C6: =SUMIF(Inventory_Master!$C$2:$C$304,A6,Inventory_Master!$H$2:$H$304) | D6: =SUMIF(Inventory_Master!$C$2:$C$304,A6,Inventory_Master!$I$2:$I$304)
A7: KITCHEN ACCESSORIES | B7: =COUNTIF(Inventory_Master!$C$2:$C$304,A7) | C7: =SUMIF(Inventory_Master!$C$2:$C$304,A7,Inventory_Master!$H$2:$H$304) | D7: =SUMIF(Inventory_Master!$C$2:$C$304,A7,Inventory_Master!$I$2:$I$304)
A8: KNOB | B8: =COUNTIF(Inventory_Master!$C$2:$C$304,A8) | C8: =SUMIF(Inventory_Master!$C$2:$C$304,A8,Inventory_Master!$H$2:$H$304) | D8: =SUMIF(Inventory_Master!$C$2:$C$304,A8,Inventory_Master!$I$2:$I$304)
A9: MFC | B9: =COUNTIF(Inventory_Master!$C$2:$C$304,A9) | C9: =SUMIF(Inventory_Master!$C$2:$C$304,A9,Inventory_Master!$H$2:$H$304) | D9: =SUMIF(Inventory_Master!$C$2:$C$304,A9,Inventory_Master!$I$2:$I$304)
A10: WARDROBE ACCESSORIES | B10: =COUNTIF(Inventory_Master!$C$2:$C$304,A10) | C10: =SUMIF(Inventory_Master!$C$2:$C$304,A10,Inventory_Master!$H$2:$H$304) | D10: =SUMIF(Inventory_Master!$C$2:$C$304,A10,Inventory_Master!$I$2:$I$304)
A11: (no category) | B11: =COUNTIF(Inventory_Master!$C$2:$C$304,"") | C11: =SUMIF(Inventory_Master!$C$2:$C$304,"",Inventory_Master!$H$2:$H$304) | D11: =SUMIF(Inventory_Master!$C$2:$C$304,"",Inventory_Master!$I$2:$I$304)
A12: Total | B12: =SUM(B2:B11) | C12: =SUM(C2:C11) | D12: =SUM(D2:D11)

Sheet Review
A1: Inventory_Master row | B1: Material_Code | C1: Material_Name | D1: Note
B2: 70*40*60CM (GREY) | C2: KITCHEN TABLEWARE STORAGE BOX | D2: Removed: repeat of source row 62 with no details or quantity (source row 642).
B3: CK 905-6 | C3: TALL UNIT BASKET SOFT CLOSING | D3: Removed: repeat of source row 63 with no details or quantity (source row 643).
B4: YS16 | C4: PULLOUT PANT RACK | D4: Removed: repeat of source row 64 with no details or quantity (source row 644).
B5: CK 907-6 | C5: SLIM PANTRY | D5: Removed: repeat of source row 65 with no details or quantity (source row 645).
A6: 2 | B6: CASHMIR-COPPER | C6: CASHMIR COPPER | D6: Material_Code was blank; this is the code the app gave it.
A7: 3 | B7: CHROME-GREY | C7: CHROME GREY | D7: Material_Code was blank; this is the code the app gave it.
A8: 4 | B8: EPHESUS-BLACK | C8: EPHESUS BLACK | D8: Material_Code was blank; this is the code the app gave it.
A9: 5 | B9: GALAXY-DORE | C9: GALAXY DORE | D9: Material_Code was blank; this is the code the app gave it.
A10: 6 | B10: H-G-DELUXE-GREY | C10: H.G DELUXE GREY | D10: Material_Code was blank; this is the code the app gave it.
A11: 7 | B11: HG-GALAXY-CREAM | C11: HG GALAXY CREAM | D11: Material_Code was blank; this is the code the app gave it.
A12: 8 | B12: HG-WHITE | C12: HG WHITE | D12: Material_Code was blank; this is the code the app gave it.
A13: 9 | B13: LUX-WHITE | C13: LUX WHITE | D13: Material_Code was blank; this is the code the app gave it.
A14: 10 | B14: MATT-STONE-GREY | C14: MATT STONE GREY | D14: Material_Code was blank; this is the code the app gave it.
A15: 11 | B15: RELAX-GREEN | C15: RELAX GREEN | D15: Material_Code was blank; this is the code the app gave it.
A16: 12 | B16: SOFT-TOUCH-OCEAN-BLUE | C16: SOFT TOUCH OCEAN BLUE | D16: Material_Code was blank; this is the code the app gave it.
A17: 13 | B17: SOFT-TOUCH-STONE-GREY | C17: SOFT TOUCH STONE GREY | D17: Material_Code was blank; this is the code the app gave it.
... A188: 290 | B188: H001 | C188: LIGHT WITH PROFILE | D188: Code shared by 2 materials; told apart by name, subcategory and dimensions.
